<?xml version="1.0" encoding="utf-8"?>
<robot xmlns:xacro="http://www.ros.org/wiki/xacro" name="avena">
  <material name="gray">
    <color rgba="0.5 0.5 0.5 1.0" />
  </material>

  <xacro:macro name="avena_arm" params="arm_id:='avena' description_pkg:='avena_bringup'">
    <!-- Links -->
    <link name="robot_base_link" />
    <link name="${arm_id}_link_0">
      <visual>
        <origin xyz="0 0 0" rpy="0 0 0" />
        <geometry>
          <mesh filename="file://$(find ${description_pkg})/urdf/meshes/avena/link_0.stl" scale="0.001 0.001 0.001" />
        </geometry>
        <material name="gray" />
      </visual>
      <inertial>
        <origin xyz="0. -0.0129 0.00034" rpy="0. 0. 0."/>
        <mass value="0.75"/>
        <inertia ixx="1."  ixy="0."  ixz="0." iyy="1." iyz="0." izz="1." />
      </inertial>
      <collision>
        <origin xyz="0 0 0" rpy="0 0 0" />
        <geometry>
          <mesh filename="file://$(find ${description_pkg})/urdf/meshes/avena/link_0.stl" scale="0.001 0.001 0.001" />
        </geometry>
      </collision>
    </link>

    <link name="${arm_id}_link_1">
      <visual>
        <origin xyz="0 0 0.0763" rpy="${pi} 0 ${-pi/2}" />
        <geometry>
          <mesh filename="file://$(find ${description_pkg})/urdf/meshes/avena/link_1.stl" scale="0.001 0.001 0.001" />
        </geometry>
        <material name="gray" />
      </visual>
      <inertial>
        <origin xyz="-0.00005 -0.007 0.0175 " rpy="0. 0. ${pi/2}"/>
        <mass value="3.5"/>
        <inertia ixx="5.372e-03"  ixy="0."  ixz="0." iyy="4.691e-03" iyz="0." izz="5.059e-03" />
      </inertial>
      <collision>
        <origin xyz="0 0 0.0763" rpy="${pi} 0 ${-pi/2}" />
        <geometry>
          <mesh filename="file://$(find ${description_pkg})/urdf/meshes/avena/link_1.stl" scale="0.001 0.001 0.001" />
        </geometry>
      </collision>
    </link>

    <link name="${arm_id}_link_2">
      <visual>
        <origin xyz="0 0 0.0763" rpy="0 ${pi} ${pi/2}" />
        <geometry>
          <mesh filename="file://$(find ${description_pkg})/urdf/meshes/avena/link_2.stl" scale="0.001 0.001 0.001" />
        </geometry>
        <material name="gray" />
      </visual>
      <inertial>
        <origin xyz="0. 0.17651 0.01528" rpy="0. 0. ${pi/2}"/>
        <mass value="6.3"/>
        <inertia ixx="2.809e-01"  ixy="0."  ixz="0." iyy="8.463e-03" iyz="0." izz="2.804e-01" />
      </inertial>
      <collision>
        <origin xyz="0 0 0.0763" rpy="0 ${pi} ${pi/2}" />
        <geometry>
          <mesh filename="file://$(find ${description_pkg})/urdf/meshes/avena/link_2.stl" scale="0.001 0.001 0.001" />
        </geometry>
      </collision>
    </link>

    <link name="${arm_id}_link_3">
      <visual>
        <origin xyz="0. 0. 0.0721" rpy="0 ${pi} ${-pi/2}" />
        <geometry>
          <mesh filename="file://$(find ${description_pkg})/urdf/meshes/avena/link_3.stl" scale="0.001 0.001 0.001" />
        </geometry>
        <material name="gray" />
      </visual>
      <inertial>
        <origin xyz="0.3046 0. 0.0588" rpy="0 0 ${pi/2}"/>
        <mass value="3.375"/>
        <inertia ixx="1.149e-01"  ixy="0"  ixz="0" iyy="4.518e-03" iyz="0" izz="1.148e-01" />
      </inertial>
      <collision>
        <origin xyz="0 0 0.0721" rpy="0 ${pi} ${-pi/2}" />
        <geometry>
          <mesh filename="file://$(find ${description_pkg})/urdf/meshes/avena/link_3.stl" scale="0.001 0.001 0.001" />
        </geometry>
      </collision>
    </link>

    <link name="${arm_id}_link_4">
      <visual>
        <origin xyz="0 0 0.064" rpy="${pi/2} 0 ${pi/2}" />
        <geometry>
          <mesh filename="file://$(find ${description_pkg})/urdf/meshes/avena/link_4.stl" scale="0.001 0.001 0.001" />
        </geometry>
        <material name="gray" />
      </visual>
      <inertial>
        <origin xyz="0.019 0. 0.059 " rpy="0. 0. ${pi/2}"/>
        <mass value="1.960"/>
        <inertia ixx="2.233e-03"  ixy="0."  ixz="0." iyy="2.047e-03" iyz="0." izz="2.384e-03" />
      </inertial>
      <collision>
        <origin xyz="0 0 0.064" rpy="${pi/2} 0 ${pi/2}" />
        <geometry>
          <mesh filename="file://$(find ${description_pkg})/urdf/meshes/avena/link_4.stl" scale="0.001 0.001 0.001" />
        </geometry>
      </collision>
    </link>

    <link name="${arm_id}_link_5">
      <visual>
        <origin xyz="0 0 0.064" rpy="${pi/2} 0 ${pi/2}" />
        <geometry>
          <mesh filename="file://$(find ${description_pkg})/urdf/meshes/avena/link_5.stl" scale="0.001 0.001 0.001" />
        </geometry>
        <material name="gray" />
      </visual>
      <inertial>
        <origin xyz="0.019 0 0.059" rpy="0. 0. ${pi/2}"/>
        <mass value="1.960"/>
        <inertia ixx="2.233e-03"  ixy="0."  ixz="0." iyy="2.047e-03" iyz="0." izz="2.384e-03" />
      </inertial>
      <collision>
        <origin xyz="0 0 0.064" rpy="${pi/2} 0 ${pi/2}" />
        <geometry>
          <mesh filename="file://$(find ${description_pkg})/urdf/meshes/avena/link_5.stl" scale="0.001 0.001 0.001" />
        </geometry>
      </collision>
    </link>

    <link name="${arm_id}_link_6">
      <visual>
        <origin xyz="0 0 0" rpy="0 0 0" />
        <geometry>
          <mesh filename="file://$(find ${description_pkg})/urdf/meshes/avena/link_6.stl" scale="0.001 0.001 0.001" />
        </geometry>
        <material name="gray" />
      </visual>
      <inertial>
        <origin xyz="0 0 0" rpy="0 0 0"/>
        <mass value="8.200e-02"/>
        <inertia ixx="4.100e-05"  ixy="0"  ixz="0" iyy="4.200e-05" iyz="0" izz="8.000e-05" />
      </inertial>
      <collision>
        <origin xyz="0 0 0" rpy="0 0 0" />
        <geometry>
          <mesh filename="file://$(find ${description_pkg})/urdf/meshes/avena/link_6.stl" scale="0.001 0.001 0.001" />
        </geometry>
      </collision>
    </link>

    <link name="${arm_id}_gripper_connection"/>

    <!-- Joints -->
    <joint name="base_joint" type="fixed">
      <origin rpy="0 0 0" xyz="0 0 0"/>
      <parent link="robot_base_link"/>
      <child link="${arm_id}_link_0"/>
      <axis xyz="0 0 0"/>
    </joint>

    <joint name="${arm_id}_joint_1" type="revolute">
      <origin xyz="0 0 0.063" rpy="0 0 -0.1963" /> <!-- Offset from position -->
      <parent link="${arm_id}_link_0" />
      <child link="${arm_id}_link_1" />
      <axis xyz="0 0 1" />
      <limit lower="-3.05" upper="3.05" effort="80" velocity="0" />
    </joint>

    <joint name="${arm_id}_joint_2" type="revolute">
      <origin xyz="0.063 0 0.0763" rpy="0 ${pi/2} 0" />
      <parent link="${arm_id}_link_1" />
      <child link="${arm_id}_link_2" />
      <axis xyz="0 0 1" />
      <limit lower="-1.57" upper="1.57" effort="180" velocity="0" />
    </joint>

    <joint name="${arm_id}_joint_3" type="revolute">
      <origin xyz="-0.467 0 0.009" rpy="0 ${pi} 0" />
      <parent link="${arm_id}_link_2" />
      <child link="${arm_id}_link_3" />
      <axis xyz="0 0 1" />
      <limit lower="-2.9" upper="2.9" effort="120" velocity="0" />
    </joint>

    <joint name="${arm_id}_joint_4" type="revolute">
      <origin xyz="0.452 0 0.0226" rpy="${pi} 0 0" />
      <parent link="${arm_id}_link_3" />
      <child link="${arm_id}_link_4" />
      <axis xyz="0 0 1" />
      <limit lower="-3.05" upper="3.05" effort="60" velocity="0" />
    </joint>

    <joint name="${arm_id}_joint_5" type="revolute">
      <origin xyz="0.0495 0 0.064" rpy="0 ${-pi/2} ${pi}" />
      <parent link="${arm_id}_link_4" />
      <child link="${arm_id}_link_5" />
      <axis xyz="0 0 1" />
      <limit lower="-3.05" upper="3.05" effort="40" velocity="0" />
    </joint>

    <joint name="${arm_id}_joint_6" type="revolute">
      <origin xyz="0.0495 0 0.064" rpy="0 ${pi/2} 0" />
      <parent link="${arm_id}_link_5" />
      <child link="${arm_id}_link_6" />
      <axis xyz="0 0 1" />
      <limit lower="-3.05" upper="3.05" effort="40" velocity="0" />
    </joint>

    <joint name="${arm_id}_joint_7" type="fixed">
      <origin xyz="0 0 0.0181" rpy="0 0 0"/>
      <parent link="${arm_id}_link_6"/>
      <child link="${arm_id}_gripper_connection"/>
      <axis xyz="0 0 0" />
    </joint>
 </xacro:macro>
</robot>
