<?xml version="1.0" ?>
<robot name="avena">
  <link name="left_avena_link_0" />
  <link name="left_avena_link_1" />
  <link name="left_avena_link_2" />
  <link name="left_avena_link_3" />
  <link name="left_avena_link_4" />
  <link name="left_avena_link_5" />
  <link name="left_avena_link_6" />
  <link name="left_avena_gripper_connection" />

  <!-- Joints -->
  <joint name="left_avena_joint_1" type="revolute">
    <origin xyz="0 0 0.063" rpy="0 0 -0.1963" />
    <parent link="left_avena_link_0"/>
    <child link="left_avena_link_1"/>
    <axis xyz="0 0 1"/>
    <limit effort="0" lower="-3.05" upper="3.05" velocity="0"/>
  </joint>
  <joint name="left_avena_joint_2" type="revolute">
    <origin xyz="0.064 0 0.0495" rpy="0 1.570796 0" />
    <parent link="left_avena_link_1"/>
    <child link="left_avena_link_2"/>
    <axis xyz="0 0 1"/>
    <limit effort="0" lower="-1.57" upper="1.57" velocity="0"/>
  </joint>
  <joint name="left_avena_joint_3" type="revolute">
    <origin xyz="-0.452 0 0" rpy="0 3.141592 0" />
    <parent link="left_avena_link_2"/>
    <child link="left_avena_link_3"/>
    <axis xyz="0 0 1"/>
    <limit effort="0" lower="-2.9" upper="2.9" velocity="0"/>
  </joint>
  <joint name="left_avena_joint_4" type="revolute">
    <origin xyz="0.452 0 0.0226" rpy="3.141592 0 0" />
    <parent link="left_avena_link_3"/>
    <child link="left_avena_link_4"/>
    <axis xyz="0 0 1"/>
    <limit effort="0" lower="-3.05" upper="3.05" velocity="0"/>
  </joint>
  <joint name="left_avena_joint_5" type="revolute">
    <origin xyz="0.0495 0 0.064" rpy="0 -1.570796 3.141592" />
    <parent link="left_avena_link_4"/>
    <child link="left_avena_link_5"/>
    <axis xyz="0 0 1"/>
    <limit effort="0" lower="-3.05" upper="3.05" velocity="0"/>
  </joint>
  <joint name="left_avena_joint_6" type="revolute">
    <origin xyz="0.0495 0 0.064" rpy="0 1.570796 0" />
    <parent link="left_avena_link_5"/>
    <child link="left_avena_link_6"/>
    <axis xyz="0 0 1"/>
    <limit effort="0" lower="-3.05" upper="3.05" velocity="0"/>
  </joint>
  <joint name="left_avena_joint_7" type="fixed">
    <origin xyz="0 0 0.0181" rpy="0 0 0"/>
    <parent link="left_avena_link_6"/>
    <child link="left_avena_gripper_connection"/>
    <axis xyz="0 0 0"/>
  </joint>
</robot>
