<?xml version="1.0" encoding="utf-8"?>
<robot xmlns:xacro="http://www.ros.org/wiki/xacro" name="avena">
  <material name="gray">
    <color rgba="0.5 0.5 0.5 1.0" />
  </material>

  <xacro:macro name="avena_arm" params="arm_id:='avena' description_pkg:='avena_bringup'">
    <link name="${arm_id}_link_0">
      <visual>
        <origin xyz="0 0 0" rpy="0 0 0" />
        <geometry>
          <mesh filename="file://$(find ${description_pkg})/urdf/meshes/avena/link_0.stl" scale="0.001 0.001 0.001" />
        </geometry>
        <material name="gray" />
      </visual>
      <collision>
        <origin xyz="0 0 0" rpy="0 0 0" />
        <geometry>
          <mesh filename="file://$(find ${description_pkg})/urdf/meshes/avena/link_0.stl" scale="0.001 0.001 0.001" />
        </geometry>
      </collision>
    </link>

    <link name="${arm_id}_link_1">
      <visual>
        <origin xyz="0 0 0.0495" rpy="${pi} 0 ${-pi/2}" />
        <geometry>
          <mesh filename="file://$(find ${description_pkg})/urdf/meshes/avena/link_1.stl" scale="0.001 0.001 0.001" />
        </geometry>
        <material name="gray" />
      </visual>
      <collision>
        <origin xyz="0 0 0.0495" rpy="${pi} 0 ${-pi/2}" />
        <geometry>
          <mesh filename="file://$(find ${description_pkg})/urdf/meshes/avena/link_1.stl" scale="0.001 0.001 0.001" />
        </geometry>
      </collision>
    </link>

    <link name="${arm_id}_link_2">
      <visual>
        <origin xyz="0 0 0.0495" rpy="0 ${pi} ${pi/2}" />
        <geometry>
          <mesh filename="file://$(find ${description_pkg})/urdf/meshes/avena/link_2.stl" scale="0.001 0.001 0.001" />
        </geometry>
        <material name="gray" />
      </visual>
      <collision>
        <origin xyz="0 0 0.0495" rpy="0 ${pi} ${pi/2}" />
        <geometry>
          <mesh filename="file://$(find ${description_pkg})/urdf/meshes/avena/link_2.stl" scale="0.001 0.001 0.001" />
        </geometry>
      </collision>
    </link>

    <link name="${arm_id}_link_3">
      <visual>
        <origin xyz="0 0 0.0721" rpy="0 ${pi} ${-pi/2}" />
        <geometry>
          <mesh filename="file://$(find ${description_pkg})/urdf/meshes/avena/link_3.stl" scale="0.001 0.001 0.001" />
        </geometry>
        <material name="gray" />
      </visual>
      <collision>
        <origin xyz="0 0 0.0721" rpy="0 ${pi} ${-pi/2}" />
        <geometry>
          <mesh filename="file://$(find ${description_pkg})/urdf/meshes/avena/link_3.stl" scale="0.001 0.001 0.001" />
        </geometry>
      </collision>
    </link>

    <link name="${arm_id}_link_4">
      <visual>
        <origin xyz="0 0 0.064" rpy="${pi/2} 0 ${pi/2}" />
        <geometry>
          <mesh filename="file://$(find ${description_pkg})/urdf/meshes/avena/link_4.stl" scale="0.001 0.001 0.001" />
        </geometry>
        <material name="gray" />
      </visual>
      <collision>
        <origin xyz="0 0 0" rpy="0 0 0" />
        <geometry>
          <mesh filename="file://$(find ${description_pkg})/urdf/meshes/avena/link_4.stl" scale="0.001 0.001 0.001" />
        </geometry>
      </collision>
    </link>

    <link name="${arm_id}_link_5">
      <visual>
        <origin xyz="0 0 0.064" rpy="${pi/2} 0 ${pi/2}" />
        <geometry>
          <mesh filename="file://$(find ${description_pkg})/urdf/meshes/avena/link_5.stl" scale="0.001 0.001 0.001" />
        </geometry>
        <material name="gray" />
      </visual>
      <collision>
        <origin xyz="0 0 0" rpy="0 0 0" />
        <geometry>
          <mesh filename="file://$(find ${description_pkg})/urdf/meshes/avena/link_5.stl" scale="0.001 0.001 0.001" />
        </geometry>
      </collision>
    </link>

    <link name="${arm_id}_link_6">
      <visual>
        <origin xyz="0 0 0" rpy="0 0 0" />
        <geometry>
          <mesh filename="file://$(find ${description_pkg})/urdf/meshes/avena/link_6.stl" scale="0.001 0.001 0.001" />
        </geometry>
        <material name="gray" />
      </visual>
      <collision>
        <origin xyz="0 0 0" rpy="0 0 0" />
        <geometry>
          <mesh filename="file://$(find ${description_pkg})/urdf/meshes/avena/link_6.stl" scale="0.001 0.001 0.001" />
        </geometry>
      </collision>
    </link>

    <link name="${arm_id}_gripper_connection"/>

    <!-- Joints -->
    <joint name="${arm_id}_joint_1" type="revolute">
      <origin xyz="0 0 0.063" rpy="0 0 0" />
      <parent link="${arm_id}_link_0" />
      <child link="${arm_id}_link_1" />
      <axis xyz="0 0 1" />
      <limit lower="-3.05" upper="3.05" effort="0" velocity="0" />
    </joint>

    <joint name="${arm_id}_joint_2" type="revolute">
      <origin xyz="0.064 0 0.0495" rpy="0 ${pi/2} 0" />
      <parent link="${arm_id}_link_1" />
      <child link="${arm_id}_link_2" />
      <axis xyz="0 0 1" />
      <limit lower="-1.57" upper="1.57" effort="0" velocity="0" />
    </joint>

    <joint name="${arm_id}_joint_3" type="revolute">
      <origin xyz="-0.452 0 0" rpy="0 ${pi} 0" />
      <parent link="${arm_id}_link_2" />
      <child link="${arm_id}_link_3" />
      <axis xyz="0 0 1" />
      <limit lower="-2.9" upper="2.9" effort="0" velocity="0" />
    </joint>

    <joint name="${arm_id}_joint_4" type="revolute">
      <origin xyz="0.452 0 0.0226" rpy="${pi} 0 0" />
      <parent link="${arm_id}_link_3" />
      <child link="${arm_id}_link_4" />
      <axis xyz="0 0 1" />
      <limit lower="-3.05" upper="3.05" effort="0" velocity="0" />
    </joint>

    <joint name="${arm_id}_joint_5" type="revolute">
      <origin xyz="0.0495 0 0.064" rpy="0 ${pi/2} 0" />
      <parent link="${arm_id}_link_4" />
      <child link="${arm_id}_link_5" />
      <axis xyz="0 0 1" />
      <limit lower="-3.05" upper="3.05" effort="0" velocity="0" />
    </joint>

    <joint name="${arm_id}_joint_6" type="revolute">
      <origin xyz="0.0495 0 0.064" rpy="0 ${pi/2} 0" />
      <parent link="${arm_id}_link_5" />
      <child link="${arm_id}_link_6" />
      <axis xyz="0 0 1" />
      <limit lower="-3.05" upper="3.05" effort="0" velocity="0" />
    </joint>

    <joint name="${arm_id}_joint_7" type="fixed">
      <origin rpy="0 0 0" xyz="0 0 0.0181"/>
      <parent link="${arm_id}_link_6"/>
      <child link="${arm_id}_gripper_connection"/>
      <axis xyz="0 0 0" />
    </joint>
 </xacro:macro>
</robot>
