<?xml version="1.0" ?>
<robot name="franka">
  <!-- Links   -->
  <link name="right_franka_link_0"/>
  <link name="right_franka_link_1"/>
  <link name="right_franka_link_2"/>
  <link name="right_franka_link_3"/>
  <link name="right_franka_link_4"/>
  <link name="right_franka_link_5"/>
  <link name="right_franka_link_6"/>
  <link name="right_franka_link_7"/>
  <link name="right_franka_gripper_connection"/>

  <joint name="right_franka_joint_1" type="revolute">
    <safety_controller k_position="100.0" k_velocity="40.0" soft_lower_limit="-2.8973" soft_upper_limit="2.8973"/>
    <origin rpy="0 0 0" xyz="0 0 0.333"/>
    <parent link="right_franka_link_0"/>
    <child link="right_franka_link_1"/>
    <axis xyz="0 0 1"/>
    <limit effort="87" lower="-2.8973" upper="2.8973" velocity="2.1750"/>
  </joint>
  <joint name="right_franka_joint_2" type="revolute">
    <safety_controller k_position="100.0" k_velocity="40.0" soft_lower_limit="-1.7628" soft_upper_limit="1.7628"/>
    <origin rpy="-1.5707963267948966 0 0" xyz="0 0 0"/>
    <parent link="right_franka_link_1"/>
    <child link="right_franka_link_2"/>
    <axis xyz="0 0 1"/>
    <limit effort="87" lower="-1.7628" upper="1.7628" velocity="2.1750"/>
  </joint>
  <joint name="right_franka_joint_3" type="revolute">
    <safety_controller k_position="100.0" k_velocity="40.0" soft_lower_limit="-2.8973" soft_upper_limit="2.8973"/>
    <origin rpy="1.5707963267948966 0 0" xyz="0 -0.316 0"/>
    <parent link="right_franka_link_2"/>
    <child link="right_franka_link_3"/>
    <axis xyz="0 0 1"/>
    <limit effort="87" lower="-2.8973" upper="2.8973" velocity="2.1750"/>
  </joint>
  <joint name="right_franka_joint_4" type="revolute">
    <safety_controller k_position="100.0" k_velocity="40.0" soft_lower_limit="-3.0718" soft_upper_limit="-0.0698"/>
    <origin rpy="1.5707963267948966 0 0" xyz="0.0825 0 0"/>
    <parent link="right_franka_link_3"/>
    <child link="right_franka_link_4"/>
    <axis xyz="0 0 1"/>
    <limit effort="87" lower="-3.0718" upper="-0.0698" velocity="2.1750"/>
  </joint>
  <joint name="right_franka_joint_5" type="revolute">
    <safety_controller k_position="100.0" k_velocity="40.0" soft_lower_limit="-2.8973" soft_upper_limit="2.8973"/>
    <origin rpy="-1.5707963267948966 0 0" xyz="-0.0825 0.384 0"/>
    <parent link="right_franka_link_4"/>
    <child link="right_franka_link_5"/>
    <axis xyz="0 0 1"/>
    <limit effort="12" lower="-2.8973" upper="2.8973" velocity="2.6100"/>
  </joint>
  <joint name="right_franka_joint_6" type="revolute">
    <safety_controller k_position="100.0" k_velocity="40.0" soft_lower_limit="-0.0175" soft_upper_limit="3.7525"/>
    <origin rpy="1.5707963267948966 0 0" xyz="0 0 0"/>
    <parent link="right_franka_link_5"/>
    <child link="right_franka_link_6"/>
    <axis xyz="0 0 1"/>
    <limit effort="12" lower="-0.0175" upper="3.7525" velocity="2.6100"/>
  </joint>
  <joint name="right_franka_joint_7" type="revolute">
    <safety_controller k_position="100.0" k_velocity="40.0" soft_lower_limit="-2.8973" soft_upper_limit="2.8973"/>
    <origin rpy="1.5707963267948966 0 0" xyz="0.088 0 0"/>
    <parent link="right_franka_link_6"/>
    <child link="right_franka_link_7"/>
    <axis xyz="0 0 1"/>
    <limit effort="12" lower="-2.8973" upper="2.8973" velocity="2.6100"/>
  </joint>
  <joint name="right_franka_joint_8" type="fixed">
    <origin rpy="0 0 -0.7853981633974483" xyz="0 0 0.107"/>
    <parent link="right_franka_link_7"/>
    <child link="right_franka_gripper_connection"/>
    <axis xyz="0 0 0"/>
  </joint>
</robot>
