<?xml version='1.0' encoding='utf-8'?>
<robot xmlns:xacro="http://www.ros.org/wiki/xacro" name="franka">
  <!-- safety_distance: Minimum safety distance in [m] by which the collision volumes are expanded and which is enforced during robot motions -->
  <!-- arm_id: Namespace of the franka arm. Serves to differentiate between arms in case of multiple instances. -->
  <xacro:macro name="franka_arm" params="arm_id:='franka' description_pkg:='avena_bringup' connected_to:='' xyz:='0 0 0' rpy:='0 0 0' safety_distance:=0">
    <!-- Links -->
    <link name="base_link" />
    <link name="${arm_id}_link_0">
      <visual>
        <geometry>
          <mesh filename="file://$(find ${description_pkg})/urdf/meshes/franka/link0.dae"/>
        </geometry>
      </visual>
      <collision>
        <geometry>
          <mesh filename="file://$(find ${description_pkg})/urdf/meshes/franka/link0.dae"/>
        </geometry>
      </collision>
    </link>
    <link name="${arm_id}_link_1">
      <visual>
        <geometry>
          <mesh filename="file://$(find ${description_pkg})/urdf/meshes/franka/link1.dae"/>
        </geometry>
      </visual>
      <collision>
        <geometry>
          <mesh filename="file://$(find ${description_pkg})/urdf/meshes/franka/link1.dae"/>
        </geometry>
      </collision>
    </link>
    <link name="${arm_id}_link_2">
      <visual>
        <geometry>
          <mesh filename="file://$(find ${description_pkg})/urdf/meshes/franka/link2.dae"/>
        </geometry>
      </visual>
      <collision>
        <geometry>
          <mesh filename="file://$(find ${description_pkg})/urdf/meshes/franka/link2.dae"/>
        </geometry>
      </collision>
    </link>
    <link name="${arm_id}_link_3">
      <visual>
        <geometry>
          <mesh filename="file://$(find ${description_pkg})/urdf/meshes/franka/link3.dae"/>
        </geometry>
      </visual>
      <collision>
        <geometry>
          <mesh filename="file://$(find ${description_pkg})/urdf/meshes/franka/link3.dae"/>
        </geometry>
      </collision>
    </link>
    <link name="${arm_id}_link_4">
      <visual>
        <geometry>
          <mesh filename="file://$(find ${description_pkg})/urdf/meshes/franka/link4.dae"/>
        </geometry>
      </visual>
      <collision>
        <geometry>
          <mesh filename="file://$(find ${description_pkg})/urdf/meshes/franka/link4.dae"/>
        </geometry>
      </collision>
    </link>
    <link name="${arm_id}_link_5">
      <visual>
        <geometry>
          <mesh filename="file://$(find ${description_pkg})/urdf/meshes/franka/link5.dae"/>
        </geometry>
      </visual>
      <collision>
        <geometry>
          <mesh filename="file://$(find ${description_pkg})/urdf/meshes/franka/link5.dae"/>
        </geometry>
      </collision>
    </link>
    <link name="${arm_id}_link_6">
      <visual>
        <geometry>
          <mesh filename="file://$(find ${description_pkg})/urdf/meshes/franka/link6.dae"/>
        </geometry>
      </visual>
      <collision>
        <geometry>
          <mesh filename="file://$(find ${description_pkg})/urdf/meshes/franka/link6.dae"/>
        </geometry>
      </collision>
    </link>
    <link name="${arm_id}_link_7">
      <visual>
        <geometry>
          <mesh filename="file://$(find ${description_pkg})/urdf/meshes/franka/link7.dae"/>
        </geometry>
      </visual>
      <collision>
        <geometry>
          <mesh filename="file://$(find ${description_pkg})/urdf/meshes/franka/link7.dae"/>
        </geometry>
      </collision>
    </link>
    <link name="${arm_id}_gripper_connection"/>

    <!-- Joints -->
    <joint name="base_joint" type="fixed">
      <origin rpy="0 0 0" xyz="0 0 0"/>
      <parent link="base_link"/>
      <child link="${arm_id}_link_0"/>
      <axis xyz="0 0 0"/>
    </joint>
    <joint name="${arm_id}_joint_1" type="revolute">
      <safety_controller k_position="100.0" k_velocity="40.0" soft_lower_limit="-2.8973" soft_upper_limit="2.8973"/>
      <origin rpy="0 0 0" xyz="0 0 0.333"/>
      <parent link="${arm_id}_link_0"/>
      <child link="${arm_id}_link_1"/>
      <axis xyz="0 0 1"/>
      <limit effort="87" lower="-2.8973" upper="2.8973" velocity="2.1750"/> 
    </joint>
    <joint name="${arm_id}_joint_2" type="revolute">
      <safety_controller k_position="100.0" k_velocity="40.0" soft_lower_limit="-1.7628" soft_upper_limit="1.7628"/>
      <origin rpy="${-pi/2} 0 0" xyz="0 0 0"/>
      <parent link="${arm_id}_link_1"/>
      <child link="${arm_id}_link_2"/>
      <axis xyz="0 0 1"/>
      <limit effort="87" lower="-1.7628" upper="1.7628" velocity="2.1750"/>
    </joint>
    <joint name="${arm_id}_joint_3" type="revolute">
      <safety_controller k_position="100.0" k_velocity="40.0" soft_lower_limit="-2.8973" soft_upper_limit="2.8973"/>
      <origin rpy="${pi/2} 0 0" xyz="0 -0.316 0"/>
      <parent link="${arm_id}_link_2"/>
      <child link="${arm_id}_link_3"/>
      <axis xyz="0 0 1"/>
      <limit effort="87" lower="-2.8973" upper="2.8973" velocity="2.1750"/>
    </joint>
    <joint name="${arm_id}_joint_4" type="revolute">
      <safety_controller k_position="100.0" k_velocity="40.0" soft_lower_limit="-3.0718" soft_upper_limit="-0.0698"/>
      <origin rpy="${pi/2} 0 0" xyz="0.0825 0 0"/>
      <parent link="${arm_id}_link_3"/>
      <child link="${arm_id}_link_4"/>
      <axis xyz="0 0 1"/>
      <limit effort="87" lower="-3.0718" upper="-0.0698" velocity="2.1750"/>
    </joint>
    <joint name="${arm_id}_joint_5" type="revolute">
      <safety_controller k_position="100.0" k_velocity="40.0" soft_lower_limit="-2.8973" soft_upper_limit="2.8973"/>
      <origin rpy="${-pi/2} 0 0" xyz="-0.0825 0.384 0"/>
      <parent link="${arm_id}_link_4"/>
      <child link="${arm_id}_link_5"/>
      <axis xyz="0 0 1"/>
      <limit effort="12" lower="-2.8973" upper="2.8973" velocity="2.6100"/>
    </joint>
    <joint name="${arm_id}_joint_6" type="revolute">
      <safety_controller k_position="100.0" k_velocity="40.0" soft_lower_limit="-0.0175" soft_upper_limit="3.7525"/>
      <origin rpy="${pi/2} 0 0" xyz="0 0 0"/>
      <parent link="${arm_id}_link_5"/>
      <child link="${arm_id}_link_6"/>
      <axis xyz="0 0 1"/>
      <limit effort="12" lower="-0.0175" upper="3.7525" velocity="2.6100"/>
    </joint>
    <joint name="${arm_id}_joint_7" type="revolute">
      <safety_controller k_position="100.0" k_velocity="40.0" soft_lower_limit="-2.8973" soft_upper_limit="2.8973"/>
      <origin rpy="${pi/2} 0 0" xyz="0.088 0 0"/>
      <parent link="${arm_id}_link_6"/>
      <child link="${arm_id}_link_7"/>
      <axis xyz="0 0 1"/>
      <limit effort="12" lower="-2.8973" upper="2.8973" velocity="2.6100"/>
    </joint>
    <joint name="${arm_id}_joint_8" type="fixed">
      <origin rpy="0 0 ${-pi/4}" xyz="0 0 0.107"/>
      <parent link="${arm_id}_link_7"/>
      <child link="${arm_id}_gripper_connection"/>
      <axis xyz="0 0 0"/>
    </joint>
  </xacro:macro>
</robot>
