<?xml version="1.0" encoding="utf-8"?>
<robot xmlns:xacro="http://www.ros.org/wiki/xacro" name="avena_urdf">


  <link name="world"/>
  <joint name="world_joint" type="fixed">
    <parent link="world"/>
    <child link="left_base_link"/>
    <origin rpy="0.0 0.0 0.0" xyz="0.0 0.0 0.0"/>
  </joint>
  <link name="left_base_link">
 <!-- temp inertia values for base link - shouldnt make a difference -->
    <inertial>
      <origin xyz="0. -0.0129 0.00034" rpy="0. 0. 0."/>
      <mass value="0.75"/>
      <inertia ixx="1."  ixy="0."  ixz="0." iyy="1." iyz="0." izz="1." />
    </inertial>
    <visual>
      <origin
        xyz="0. 0. 0."
        rpy="0. 0. 0." />
      <geometry>
        <mesh
          filename="package://avena_bringup/meshes/base_link.stl" />
      </geometry>
      
      <material
        name="">
        <color
          rgba="0.898039215686275 0.917647058823529 0.929411764705882 1" />
      </material>
    </visual>
    <collision>
      <origin
        xyz="0. 0. 0."
        rpy="0. 0. 0." />
      <geometry>
        <mesh
          filename="package://avena_bringup/meshes/base_link.stl" />
      </geometry>
    </collision>
  </link>
  <joint
    name="left_joint_1"
    type="revolute">
    <origin
      xyz="0. 0. 0.047"
      rpy="3.1416 0. 1.5708" />
    <parent
      link="left_base_link" />
    <child
      link="left_link_1" />
    <axis
      xyz="0. 0. -1." />
    <limit
      lower="-3.05"
      upper="3.05"
      effort="30."
      velocity="0." />
  </joint>
  <link
    name="left_link_1">
    <visual>
      <origin
        xyz="0. 0. 0."
        rpy="0. 0. 0." />
      <geometry>
        <mesh
          filename="package://avena_bringup/meshes/Link_1.stl" />
      </geometry>
      <material
        name="">
        <color
          rgba="0.752941176470588 0.752941176470588 0.752941176470588 1." />
      </material>
    </visual>
    <collision>
      <origin
        xyz="0. 0. 0."
        rpy="0. 0. 0." />
      <geometry>
        <mesh
          filename="package://avena_bringup/meshes/Link_1.stl" />
      </geometry>
    </collision>
    <inertial>
      <origin xyz="-0.00002 -0.00677 -0.02226" rpy="0. 0. 0."/>
      <mass value="1.3"/>
      <inertia ixx="1.817e-03"  ixy="0."  ixz="0." iyy="1.655e-03" iyz="0." izz="1.897e-03" />
    </inertial>
  </link>
  <joint
    name="left_joint_2"
    type="revolute">
    <origin
      xyz="0. 0.048 -0.0679"
      rpy="-1.5708 0. 0." />
    <parent
      link="left_link_1" />
    <child
      link="left_link_2" />
    <axis
      xyz="0. 0. 1." />
    <limit
      lower="-1.57"
      upper="1.57"
      effort="45."
      velocity="0." />
  </joint>
  <link
    name="left_link_2">
    <visual>
      <origin
        xyz="0. 0. 0."
        rpy="0. 0. 0." />
      <geometry>
        <mesh
          filename="package://avena_bringup/meshes/Link_2.stl" />
      </geometry>
      <material
        name="">
        <color
          rgba="0.752941176470588 0.752941176470588 0.752941176470588 1." />
      </material>
    </visual>
    <collision>
      <origin
        xyz="0. 0. 0."
        rpy="0. 0. 0." />
      <geometry>
        <mesh
          filename="package://avena_bringup/meshes/Link_2.stl" />
      </geometry>
    </collision>
    <inertial>
      <origin xyz="0. 0.256 0.05115" rpy="0. 0. 0."/>
      <mass value="3.8"/>
      <inertia ixx="1.472e-01"  ixy="0."  ixz="0." iyy="1.470e-01" iyz="0." izz="4.882e-03" />
    </inertial>
  </link>
  <link
    name="left_link_3">
    
     <visual>
      <origin
        xyz="0 0 0"
        rpy="0 0 0" />
      <geometry>
        <mesh
          filename="package://avena_bringup/meshes/Link_3.stl" />
      </geometry>
      <material
        name="">
        <color
          rgba="0.752941176470588 0.752941176470588 0.752941176470588 1" />
      </material>
    </visual>
    <collision>
      <origin
        xyz="0 0 0"
        rpy="0 0 0" />
      <geometry>
        <mesh
          filename="package://avena_bringup/meshes/Link_3.stl" />
      </geometry>
    </collision>
    <inertial>
      <origin xyz="0 0 0" rpy="0 0 0"/>
      <mass value="2.15"/>
      <inertia ixx="7.603e-02"  ixy="0"  ixz="0" iyy="7.582e-02" iyz="0" izz="3.239e-03" />
    </inertial>
  </link>
  <joint
    name="left_joint_3"
    type="revolute">
    <origin
      xyz="0 0.452 0"
      rpy="0 0 0" />
    <parent
      link="left_link_2" />
    <child
      link="left_link_3" />
    <axis
      xyz="0 0 1" />
    <limit
      lower="-2.9"
      upper="2.9"
      effort="0"
      velocity="0" />
  </joint>
  <link
    name="left_link_4">
    
    <visual>
      <origin
        xyz="0 0 0"
        rpy="0 0 0" />
      <geometry>
        <mesh
          filename="package://avena_bringup/meshes/Link_4.stl" />
      </geometry>
      <material
        name="">
        <color
          rgba="0.898039215686275 0.917647058823529 0.929411764705882 1" />
      </material>
    </visual>
    <collision>
      <origin
        xyz="0 0 0"
        rpy="0 0 0" />
      <geometry>
        <mesh
          filename="package://avena_bringup/meshes/Link_4.stl" />
      </geometry>
    </collision>
    <inertial>
      <origin xyz="0 0 0" rpy="0 0 0"/>
      <mass value="1.3"/>
      <inertia ixx="1.817e-03"  ixy="0"  ixz="0" iyy="1.655e-03" iyz="0" izz="1.897e-03" />
    </inertial>
  </link>
  <joint
    name="left_joint_4"
    type="revolute">
    <origin
      xyz="0 0.447 0.0006"
      rpy="1.5708 0 0" />
    <parent
      link="left_link_3" />
    <child
      link="left_link_4" />
    <axis
      xyz="0 1 0" />
    <limit
      lower="-3.05"
      upper="3.05"
      effort="0"
      velocity="0" />
  </joint>
  <link
    name="left_link_5">
    
    <visual>
      <origin
        xyz="0 0 0"
        rpy="0 0 0" />
      <geometry>
        <mesh
          filename="package://avena_bringup/meshes/Link_5.stl" />
      </geometry>
      <material
        name="">
        <color
          rgba="0.898039215686275 0.917647058823529 0.929411764705882 1" />
      </material>
    </visual>
    <collision>
      <origin
        xyz="0 0 0"
        rpy="0 0 0" />
      <geometry>
        <mesh
          filename="package://avena_bringup/meshes/Link_5.stl" />
      </geometry>
    </collision>
    <inertial>
      <origin xyz="0 0 0" rpy="0 0 0"/>
      <mass value="1.33"/>
      <inertia ixx="1.817e-03"  ixy="0"  ixz="0" iyy="1.897e-03" iyz="0" izz="1.655e-03" />
    </inertial>
  </link>
  <joint
    name="left_joint_5"
    type="revolute">
    <origin
      xyz="0 0.055 -0.0567"
      rpy="1.5708 0 3.1416" />
    <parent
      link="left_link_4" />
    <child
      link="left_link_5" />
    <axis
      xyz="0 -1 0" />
    <limit
      lower="-3.05"
      upper="3.05"
      effort="0"
      velocity="0" />
  </joint>
  <!-- <link
    name="left_link_6">
    
    <visual>
      <origin
        xyz="0 0 0"
        rpy="0 0 0" />
      <geometry>
        <mesh
          filename="package://avena_bringup/meshes/Link_6.stl" />
      </geometry>
      <material
        name="">
        <color
          rgba="0.898039215686275 0.917647058823529 0.929411764705882 1" />
      </material>
    </visual>
    <collision>
      <origin
        xyz="0 0 0"
        rpy="0 0 0" />
      <geometry>
        <mesh
          filename="package://avena_bringup/meshes/Link_6.stl" />
      </geometry>
    </collision>
    <inertial>
      <origin xyz="0 0 0" rpy="0 0 0"/>
      <mass value="8.200e-02"/>
      <inertia ixx="4.100e-05"  ixy="0"  ixz="0" iyy="4.200e-05" iyz="0" izz="8.000e-05" />
    </inertial>
  </link> -->
  <!-- <joint
    name="left_joint_6"
    type="revolute">
    <origin
      xyz="0 -0.055 0.0567"
      rpy="-1.5708 0 0.785" />
    <parent
      link="left_link_5" />
    <child
      link="left_link_6" />
    <axis
      xyz="0 -1 0" />
    <limit
      lower="-3.05"
      upper="3.05"
      effort="0"
      velocity="0" />
  </joint>
    <link name="Panda_gripper">
      <collision>
        <origin xyz="0 0 0" rpy="0 0 0"/>
        <geometry>
          <cylinder radius="0.03"  length="0.01" />
        </geometry>
      </collision>
      <collision>
        <origin xyz="0.0424 0.0424 -0.02" rpy="0 0 0"/>
        <geometry>
          <sphere radius="0.03"  />
        </geometry>
      </collision>
      <collision>
        <origin xyz="0.0424 0.0424 -0.03" rpy="0 0 0"/>
        <geometry>
          <sphere radius="0.03"  />
        </geometry>
      </collision>
      <inertial>
        <origin xyz="0 1 1" rpy="0 0 0"/>
        <mass value="8.200e02"/>
        <inertia ixx="4.100e-05"  ixy="0"  ixz="0" iyy="4.200e-05" iyz="0" izz="8.000e-05" />
      </inertial>
    </link>

    <joint name="left_joint_7" type="fixed">
      <origin rpy="-0.985 -1.57 2.55" xyz="0 -0.027 0"/>
      <parent link="left_link_6"/>
      <child link="Panda_gripper"/>
    </joint> -->

</robot>
